{
    "url": "https://api.github.com/repos/dask/dask/issues/7015",
    "repository_url": "https://api.github.com/repos/dask/dask",
    "labels_url": "https://api.github.com/repos/dask/dask/issues/7015/labels{/name}",
    "comments_url": "https://api.github.com/repos/dask/dask/issues/7015/comments",
    "events_url": "https://api.github.com/repos/dask/dask/issues/7015/events",
    "html_url": "https://github.com/dask/dask/issues/7015",
    "id": 775511000,
    "node_id": "MDU6SXNzdWU3NzU1MTEwMDA=",
    "number": 7015,
    "title": "\"Gaps in blk ref_locs\" error during join on categorical column",
    "user": {
        "login": "jangorecki",
        "id": 3627377,
        "node_id": "MDQ6VXNlcjM2MjczNzc=",
        "avatar_url": "https://avatars.githubusercontent.com/u/3627377?v=4",
        "gravatar_id": "",
        "url": "https://api.github.com/users/jangorecki",
        "html_url": "https://github.com/jangorecki",
        "followers_url": "https://api.github.com/users/jangorecki/followers",
        "following_url": "https://api.github.com/users/jangorecki/following{/other_user}",
        "gists_url": "https://api.github.com/users/jangorecki/gists{/gist_id}",
        "starred_url": "https://api.github.com/users/jangorecki/starred{/owner}{/repo}",
        "subscriptions_url": "https://api.github.com/users/jangorecki/subscriptions",
        "organizations_url": "https://api.github.com/users/jangorecki/orgs",
        "repos_url": "https://api.github.com/users/jangorecki/repos",
        "events_url": "https://api.github.com/users/jangorecki/events{/privacy}",
        "received_events_url": "https://api.github.com/users/jangorecki/received_events",
        "type": "User",
        "site_admin": false
    },
    "labels": [
        {
            "id": 242862289,
            "node_id": "MDU6TGFiZWwyNDI4NjIyODk=",
            "url": "https://api.github.com/repos/dask/dask/labels/dataframe",
            "name": "dataframe",
            "color": "fbca04",
            "default": false,
            "description": null
        }
    ],
    "state": "open",
    "locked": false,
    "assignee": null,
    "assignees": [],
    "milestone": null,
    "comments": 1,
    "created_at": "2020-12-28T17:39:13Z",
    "updated_at": "2021-01-05T16:41:30Z",
    "closed_at": null,
    "author_association": "NONE",
    "active_lock_reason": null,
    "body": "**What happened**:\r\n\r\nConfusing error that does not provide really any useful information for user, and seems more like an internal error.\r\n\r\n**What you expected to happen**:\r\n\r\nNo error, join computed successfully. Eventually an error which is more meaningful.\r\n\r\n**Minimal Complete Verifiable Example**:\r\n\r\nI tried to provide minimal example but it does work properly on a 2-3 rows datasets. Below code generates 0.5 GB dataset.\r\n\r\n```sh\r\nwget https://raw.githubusercontent.com/h2oai/db-benchmark/f9a6ce54db7d7b6cdab0780306c990f197a5e3e0/_data/join-datagen.R\r\nRscript join-datagen.R 1e7 0 5 0\r\npython\r\n```\r\n\r\nReproduce error\r\n```py\r\nimport dask as dk\r\nimport dask.dataframe as dd\r\nfrom dask import distributed\r\nclient = distributed.Client(processes=True, silence_logs=logging.ERROR)\r\ndk.config.set({\"optimization.fuse.ave-width\": 20})\r\ndk.__version__\r\n#'2020.12.0'\r\nx = dd.read_csv('J1_1e7_NA_5_0.csv', dtype={'id1':'Int32','id2':'Int32','id3':'Int32','id4':'category','id5':'category','id6':'category','v1':'float64'}).persist()\r\nmedium = dd.read_csv('J1_1e7_1e4_5_0.csv', dtype={'id1':'Int32','id2':'Int32','id4':'category','id5':'category','v2':'float64'}).persist()\r\nans = x.merge(medium, on='id5').compute()\r\n```\r\n```\r\nTraceback (most recent call last):\r\n  File \"<stdin>\", line 1, in <module>\r\n  File \"/home/jan/git/db-benchmark/dask/py-dask/lib/python3.6/site-packages/dask/base.py\", line 279, in compute\r\n    (result,) = compute(self, traverse=False, **kwargs)\r\n  File \"/home/jan/git/db-benchmark/dask/py-dask/lib/python3.6/site-packages/dask/base.py\", line 567, in compute\r\n    results = schedule(dsk, keys, **kwargs)\r\n  File \"/home/jan/git/db-benchmark/dask/py-dask/lib/python3.6/site-packages/dask/threaded.py\", line 84, in get\r\n    **kwargs\r\n  File \"/home/jan/git/db-benchmark/dask/py-dask/lib/python3.6/site-packages/dask/local.py\", line 486, in get_async\r\n    raise_exception(exc, tb)\r\n  File \"/home/jan/git/db-benchmark/dask/py-dask/lib/python3.6/site-packages/dask/local.py\", line 316, in reraise\r\n    raise exc\r\n  File \"/home/jan/git/db-benchmark/dask/py-dask/lib/python3.6/site-packages/dask/local.py\", line 222, in execute_task\r\n    result = _execute_task(task, data)\r\n  File \"/home/jan/git/db-benchmark/dask/py-dask/lib/python3.6/site-packages/dask/core.py\", line 121, in _execute_task\r\n    return func(*(_execute_task(a, cache) for a in args))\r\n  File \"/home/jan/git/db-benchmark/dask/py-dask/lib/python3.6/site-packages/dask/utils.py\", line 30, in apply\r\n    return func(*args, **kwargs)\r\n  File \"/home/jan/git/db-benchmark/dask/py-dask/lib/python3.6/site-packages/dask/dataframe/multi.py\", line 274, in merge_chunk\r\n    out = lhs.merge(rhs, *args, **kwargs)\r\n  File \"/home/jan/git/db-benchmark/dask/py-dask/lib/python3.6/site-packages/pandas/core/frame.py\", line 7963, in merge\r\n    validate=validate,\r\n  File \"/home/jan/git/db-benchmark/dask/py-dask/lib/python3.6/site-packages/pandas/core/reshape/merge.py\", line 87, in merge\r\n    validate=validate,\r\n  File \"/home/jan/git/db-benchmark/dask/py-dask/lib/python3.6/site-packages/pandas/core/reshape/merge.py\", line 652, in __init__\r\n    ) = self._get_merge_keys()\r\n  File \"/home/jan/git/db-benchmark/dask/py-dask/lib/python3.6/site-packages/pandas/core/reshape/merge.py\", line 1063, in _get_merge_\r\nkeys\r\n    self.right = self.right._drop_labels_or_levels(right_drop)\r\n  File \"/home/jan/git/db-benchmark/dask/py-dask/lib/python3.6/site-packages/pandas/core/generic.py\", line 1646, in _drop_labels_or_l\r\nevels\r\n    dropped.drop(labels_to_drop, axis=1, inplace=True)\r\n  File \"/home/jan/git/db-benchmark/dask/py-dask/lib/python3.6/site-packages/pandas/core/frame.py\", line 4174, in drop\r\n    errors=errors,\r\n  File \"/home/jan/git/db-benchmark/dask/py-dask/lib/python3.6/site-packages/pandas/core/generic.py\", line 3889, in drop\r\n    obj = obj._drop_axis(labels, axis, level=level, errors=errors)\r\n  File \"/home/jan/git/db-benchmark/dask/py-dask/lib/python3.6/site-packages/pandas/core/generic.py\", line 3924, in _drop_axis\r\n    result = self.reindex(**{axis_name: new_axis})\r\n  File \"/home/jan/git/db-benchmark/dask/py-dask/lib/python3.6/site-packages/pandas/util/_decorators.py\", line 309, in wrapper\r\n    return func(*args, **kwargs)\r\n  File \"/home/jan/git/db-benchmark/dask/py-dask/lib/python3.6/site-packages/pandas/core/frame.py\", line 4036, in reindex\r\n    return super().reindex(**kwargs)\r\n  File \"/home/jan/git/db-benchmark/dask/py-dask/lib/python3.6/site-packages/pandas/core/generic.py\", line 4464, in reindex\r\n    axes, level, limit, tolerance, method, fill_value, copy\r\n  File \"/home/jan/git/db-benchmark/dask/py-dask/lib/python3.6/site-packages/pandas/core/frame.py\", line 3877, in _reindex_axes\r\n    columns, method, copy, level, fill_value, limit, tolerance\r\n  File \"/home/jan/git/db-benchmark/dask/py-dask/lib/python3.6/site-packages/pandas/core/frame.py\", line 3925, in _reindex_columns\r\n    allow_dups=False,\r\n  File \"/home/jan/git/db-benchmark/dask/py-dask/lib/python3.6/site-packages/pandas/core/generic.py\", line 4532, in _reindex_with_ind\r\nexers\r\n    copy=copy,\r\n  File \"/home/jan/git/db-benchmark/dask/py-dask/lib/python3.6/site-packages/pandas/core/internals/managers.py\", line 1291, in reinde\r\nx_indexer\r\n    new_blocks = self._slice_take_blocks_ax0(indexer, fill_value=fill_value)\r\n  File \"/home/jan/git/db-benchmark/dask/py-dask/lib/python3.6/site-packages/pandas/core/internals/managers.py\", line 1371, in _slice\r\n_take_blocks_ax0\r\n    self.blknos, slobj, fill_value=-1, allow_fill=allow_fill\r\n  File \"/home/jan/git/db-benchmark/dask/py-dask/lib/python3.6/site-packages/pandas/core/internals/managers.py\", line 175, in blknos\r\n    self._rebuild_blknos_and_blklocs()\r\n  File \"/home/jan/git/db-benchmark/dask/py-dask/lib/python3.6/site-packages/pandas/core/internals/managers.py\", line 254, in _rebuil\r\nd_blknos_and_blklocs\r\n    raise AssertionError(\"Gaps in blk ref_locs\")\r\nAssertionError: Gaps in blk ref_locs\r\n```\r\n\r\n**Anything else we need to know?**:\r\n\r\n**Environment**:\r\n\r\n- Dask version: 2020.12.0\r\n- Python version: 3.6\r\n- Operating System: Linux\r\n- Install method (conda, pip, source): pip\r\n",
    "closed_by": null,
    "reactions": {
        "url": "https://api.github.com/repos/dask/dask/issues/7015/reactions",
        "total_count": 0,
        "+1": 0,
        "-1": 0,
        "laugh": 0,
        "hooray": 0,
        "confused": 0,
        "heart": 0,
        "rocket": 0,
        "eyes": 0
    },
    "timeline_url": "https://api.github.com/repos/dask/dask/issues/7015/timeline",
    "performed_via_github_app": null,
    "state_reason": null
}