{
    "url": "https://api.github.com/repos/dask/dask/issues/3590",
    "repository_url": "https://api.github.com/repos/dask/dask",
    "labels_url": "https://api.github.com/repos/dask/dask/issues/3590/labels{/name}",
    "comments_url": "https://api.github.com/repos/dask/dask/issues/3590/comments",
    "events_url": "https://api.github.com/repos/dask/dask/issues/3590/events",
    "html_url": "https://github.com/dask/dask/issues/3590",
    "id": 331282857,
    "node_id": "MDU6SXNzdWUzMzEyODI4NTc=",
    "number": 3590,
    "title": "Automatically coerce map_blocks results to correct dimension",
    "user": {
        "login": "tjcrone",
        "id": 5667194,
        "node_id": "MDQ6VXNlcjU2NjcxOTQ=",
        "avatar_url": "https://avatars.githubusercontent.com/u/5667194?v=4",
        "gravatar_id": "",
        "url": "https://api.github.com/users/tjcrone",
        "html_url": "https://github.com/tjcrone",
        "followers_url": "https://api.github.com/users/tjcrone/followers",
        "following_url": "https://api.github.com/users/tjcrone/following{/other_user}",
        "gists_url": "https://api.github.com/users/tjcrone/gists{/gist_id}",
        "starred_url": "https://api.github.com/users/tjcrone/starred{/owner}{/repo}",
        "subscriptions_url": "https://api.github.com/users/tjcrone/subscriptions",
        "organizations_url": "https://api.github.com/users/tjcrone/orgs",
        "repos_url": "https://api.github.com/users/tjcrone/repos",
        "events_url": "https://api.github.com/users/tjcrone/events{/privacy}",
        "received_events_url": "https://api.github.com/users/tjcrone/received_events",
        "type": "User",
        "site_admin": false
    },
    "labels": [
        {
            "id": 242862305,
            "node_id": "MDU6TGFiZWwyNDI4NjIzMDU=",
            "url": "https://api.github.com/repos/dask/dask/labels/array",
            "name": "array",
            "color": "006b75",
            "default": false,
            "description": null
        }
    ],
    "state": "open",
    "locked": false,
    "assignee": null,
    "assignees": [],
    "milestone": null,
    "comments": 38,
    "created_at": "2018-06-11T17:37:33Z",
    "updated_at": "2019-04-04T22:36:50Z",
    "closed_at": null,
    "author_association": "NONE",
    "active_lock_reason": null,
    "body": "I have a Dask array of 120 HD images built from a stack of delayed objects:\r\n```\r\ndask.array<stack, shape=(120, 1080, 1920), dtype=uint16, chunksize=(1, 1080, 1920)>\r\n```\r\nand I am trying to apply a function, which returns an int64, to each image using map_blocks:\r\n```\r\nfloc_proxy = dsa.map_blocks(calc_floc_proxy, delayed_frame_array, d1, d2, n, dtype='i8', drop_axis=[1,2])\r\nfloc_proxy\r\ndask.array<calc_floc_proxy, shape=(120,), dtype=int64, chunksize=(1,)>\r\n```\r\nwhen I do floc_proxy.compute(), it runs through all the calculations for each image just fine, but fails at the very end with the following error:\r\n```\r\n---------------------------------------------------------------------------\r\nIndexError                                Traceback (most recent call last)\r\n<ipython-input-102-4aab0a1a8291> in <module>()\r\n----> 1 floc_proxy.compute()\r\n\r\n/opt/conda/lib/python3.6/site-packages/dask/base.py in compute(self, **kwargs)\r\n    153         dask.base.compute\r\n    154         \"\"\"\r\n--> 155         (result,) = compute(self, traverse=False, **kwargs)\r\n    156         return result\r\n    157 \r\n\r\n/opt/conda/lib/python3.6/site-packages/dask/base.py in compute(*args, **kwargs)\r\n    405     results_iter = iter(results)\r\n    406     return tuple(a if f is None else f(next(results_iter), *a)\r\n--> 407                  for f, a in postcomputes)\r\n    408 \r\n    409 \r\n\r\n/opt/conda/lib/python3.6/site-packages/dask/base.py in <genexpr>(.0)\r\n    405     results_iter = iter(results)\r\n    406     return tuple(a if f is None else f(next(results_iter), *a)\r\n--> 407                  for f, a in postcomputes)\r\n    408 \r\n    409 \r\n\r\n/opt/conda/lib/python3.6/site-packages/dask/array/core.py in finalize(results)\r\n    991     while isinstance(results2, (tuple, list)):\r\n    992         if len(results2) > 1:\r\n--> 993             return concatenate3(results)\r\n    994         else:\r\n    995             results2 = results2[0]\r\n\r\n/opt/conda/lib/python3.6/site-packages/dask/array/core.py in concatenate3(arrays)\r\n   3355     if not ndim:\r\n   3356         return arrays\r\n-> 3357     chunks = chunks_from_arrays(arrays)\r\n   3358     shape = tuple(map(sum, chunks))\r\n   3359 \r\n\r\n/opt/conda/lib/python3.6/site-packages/dask/array/core.py in chunks_from_arrays(arrays)\r\n   3181 \r\n   3182     while isinstance(arrays, (list, tuple)):\r\n-> 3183         result.append(tuple([shape(deepfirst(a))[dim] for a in arrays]))\r\n   3184         arrays = arrays[0]\r\n   3185         dim += 1\r\n\r\n/opt/conda/lib/python3.6/site-packages/dask/array/core.py in <listcomp>(.0)\r\n   3181 \r\n   3182     while isinstance(arrays, (list, tuple)):\r\n-> 3183         result.append(tuple([shape(deepfirst(a))[dim] for a in arrays]))\r\n   3184         arrays = arrays[0]\r\n   3185         dim += 1\r\n\r\nIndexError: tuple index out of range\r\n```\r\nAny ideas what I'm doing wrong? Could this be a bug?\r\n",
    "closed_by": null,
    "reactions": {
        "url": "https://api.github.com/repos/dask/dask/issues/3590/reactions",
        "total_count": 0,
        "+1": 0,
        "-1": 0,
        "laugh": 0,
        "hooray": 0,
        "confused": 0,
        "heart": 0,
        "rocket": 0,
        "eyes": 0
    },
    "timeline_url": "https://api.github.com/repos/dask/dask/issues/3590/timeline",
    "performed_via_github_app": null,
    "state_reason": null
}