{
    "url": "https://api.github.com/repos/dask/dask/issues/9067",
    "repository_url": "https://api.github.com/repos/dask/dask",
    "labels_url": "https://api.github.com/repos/dask/dask/issues/9067/labels{/name}",
    "comments_url": "https://api.github.com/repos/dask/dask/issues/9067/comments",
    "events_url": "https://api.github.com/repos/dask/dask/issues/9067/events",
    "html_url": "https://github.com/dask/dask/issues/9067",
    "id": 1232794941,
    "node_id": "I_kwDOAbcwm85JevU9",
    "number": 9067,
    "title": "Unexpected `AttributeError` on `Series.cumsum`",
    "user": {
        "login": "charlesbluca",
        "id": 20627856,
        "node_id": "MDQ6VXNlcjIwNjI3ODU2",
        "avatar_url": "https://avatars.githubusercontent.com/u/20627856?v=4",
        "gravatar_id": "",
        "url": "https://api.github.com/users/charlesbluca",
        "html_url": "https://github.com/charlesbluca",
        "followers_url": "https://api.github.com/users/charlesbluca/followers",
        "following_url": "https://api.github.com/users/charlesbluca/following{/other_user}",
        "gists_url": "https://api.github.com/users/charlesbluca/gists{/gist_id}",
        "starred_url": "https://api.github.com/users/charlesbluca/starred{/owner}{/repo}",
        "subscriptions_url": "https://api.github.com/users/charlesbluca/subscriptions",
        "organizations_url": "https://api.github.com/users/charlesbluca/orgs",
        "repos_url": "https://api.github.com/users/charlesbluca/repos",
        "events_url": "https://api.github.com/users/charlesbluca/events{/privacy}",
        "received_events_url": "https://api.github.com/users/charlesbluca/received_events",
        "type": "User",
        "site_admin": false
    },
    "labels": [
        {
            "id": 242862289,
            "node_id": "MDU6TGFiZWwyNDI4NjIyODk=",
            "url": "https://api.github.com/repos/dask/dask/labels/dataframe",
            "name": "dataframe",
            "color": "fbca04",
            "default": false,
            "description": null
        },
        {
            "id": 386719598,
            "node_id": "MDU6TGFiZWwzODY3MTk1OTg=",
            "url": "https://api.github.com/repos/dask/dask/labels/documentation",
            "name": "documentation",
            "color": "f9d0c4",
            "default": true,
            "description": "Improve or add to documentation"
        },
        {
            "id": 996497175,
            "node_id": "MDU6TGFiZWw5OTY0OTcxNzU=",
            "url": "https://api.github.com/repos/dask/dask/labels/good%20second%20issue",
            "name": "good second issue",
            "color": "5319e7",
            "default": false,
            "description": "Clearly described, educational, but less trivial than \"good first issue\"."
        }
    ],
    "state": "open",
    "locked": false,
    "assignee": null,
    "assignees": [],
    "milestone": null,
    "comments": 2,
    "created_at": "2022-05-11T15:00:06Z",
    "updated_at": "2022-07-22T12:16:26Z",
    "closed_at": null,
    "author_association": "MEMBER",
    "active_lock_reason": null,
    "body": "<!-- Please include a self-contained copy-pastable example that generates the issue if possible.\r\n\r\nPlease be concise with code posted. See guidelines below on how to provide a good bug report:\r\n\r\n- Craft Minimal Bug Reports http://matthewrocklin.com/blog/work/2018/02/28/minimal-bug-reports\r\n- Minimal Complete Verifiable Examples https://stackoverflow.com/help/mcve\r\n\r\nBug reports that follow these guidelines are easier to diagnose, and so are often handled much more quickly.\r\n-->\r\n\r\n**What happened**:\r\nWhen attempting to compute `cumsum` on a series that is the result of a `map_partitions` call, I am getting an unexpected `AttributeError`:\r\n\r\n```python\r\nTraceback (most recent call last):\r\n  File \"/datasets/charlesb/dev/rapids/dask-sql/test.py\", line 6, in <module>\r\n    res = ddf.map_partitions(lambda x: 1).cumsum().compute()\r\n  File \"/datasets/charlesb/dev/rapids/dask/dask/base.py\", line 311, in compute\r\n    (result,) = compute(self, traverse=False, **kwargs)\r\n  File \"/datasets/charlesb/dev/rapids/dask/dask/base.py\", line 599, in compute\r\n    results = schedule(dsk, keys, **kwargs)\r\n  File \"/datasets/charlesb/dev/rapids/dask/dask/threaded.py\", line 81, in get\r\n    results = get_async(\r\n  File \"/datasets/charlesb/dev/rapids/dask/dask/local.py\", line 508, in get_async\r\n    raise_exception(exc, tb)\r\n  File \"/datasets/charlesb/dev/rapids/dask/dask/local.py\", line 316, in reraise\r\n    raise exc\r\n  File \"/datasets/charlesb/dev/rapids/dask/dask/local.py\", line 221, in execute_task\r\n    result = _execute_task(task, data)\r\n  File \"/datasets/charlesb/dev/rapids/dask/dask/core.py\", line 119, in _execute_task\r\n    return func(*(_execute_task(a, cache) for a in args))\r\n  File \"/datasets/charlesb/dev/rapids/dask/dask/optimization.py\", line 990, in __call__\r\n    return core.get(self.dsk, self.outkey, dict(zip(self.inkeys, args)))\r\n  File \"/datasets/charlesb/dev/rapids/dask/dask/core.py\", line 149, in get\r\n    result = _execute_task(task, cache)\r\n  File \"/datasets/charlesb/dev/rapids/dask/dask/core.py\", line 119, in _execute_task\r\n    return func(*(_execute_task(a, cache) for a in args))\r\n  File \"/datasets/charlesb/dev/rapids/dask/dask/utils.py\", line 40, in apply\r\n    return func(*args, **kwargs)\r\n  File \"/datasets/charlesb/dev/rapids/dask/dask/dataframe/core.py\", line 6429, in apply_and_enforce\r\n    df = func(*args, **kwargs)\r\n  File \"/datasets/charlesb/dev/rapids/dask/dask/utils.py\", line 1046, in __call__\r\n    return getattr(__obj, self.method)(*args, **kwargs)\r\nAttributeError: 'int' object has no attribute 'cumsum'\r\n```\r\n\r\n**What you expected to happen**:\r\nThe same code works if I compute the result of the `map_partitions` call prior to computing `cumsum`, so I would expect that result regardless of intermediate computes.\r\n\r\n**Minimal Complete Verifiable Example**:\r\nThis fails:\r\n\r\n```python\r\nimport dask.dataframe as dd\r\nimport pandas as pd\r\n\r\nddf = dd.from_pandas(pd.DataFrame({\"a\": range(10)}), 2)\r\n\r\nres = ddf.map_partitions(lambda x: len(x)).cumsum().compute()\r\n```\r\n\r\nWhile this succeeds:\r\n\r\n```python\r\nres = ddf.map_partitions(lambda x: len(x)).compute().cumsum()\r\n```\r\n\r\n**Environment**:\r\n\r\n- Dask version: latest `main`\r\n- Python version: 3.9\r\n- Operating System: ubuntu 20.04\r\n- Install method (conda, pip, source): source",
    "closed_by": null,
    "reactions": {
        "url": "https://api.github.com/repos/dask/dask/issues/9067/reactions",
        "total_count": 0,
        "+1": 0,
        "-1": 0,
        "laugh": 0,
        "hooray": 0,
        "confused": 0,
        "heart": 0,
        "rocket": 0,
        "eyes": 0
    },
    "timeline_url": "https://api.github.com/repos/dask/dask/issues/9067/timeline",
    "performed_via_github_app": null,
    "state_reason": null
}